import{_ as a,c as o,o as r,a as e,b as t}from"./app.6aa4d79c.js";var n="/CommonErrors_banner.png";const M='{"title":"Common errors","description":"","frontmatter":{},"headers":[{"level":2,"title":"1.","slug":"_1"},{"level":3,"title":"Solution","slug":"solution"},{"level":2,"title":"2.","slug":"_2"},{"level":3,"title":"Solution","slug":"solution-1"},{"level":2,"title":"3.","slug":"_3"},{"level":3,"title":"Solution","slug":"solution-2"},{"level":2,"title":"4.","slug":"_4"},{"level":3,"title":"Solution","slug":"solution-3"}],"relativePath":"errors.md","lastUpdated":1642064870104}',i={},s=e("p",null,[e("img",{src:n,alt:"An image"})],-1),l=e("h1",{id:"common-errors",tabindex:"-1"},[t("Common errors "),e("a",{class:"header-anchor",href:"#common-errors","aria-hidden":"true"},"#")],-1),c=e("p",null,"This section features common errors that might be encountered when setting up the page or might be encountered when further developing on this platform.",-1),d=e("h2",{id:"_1",tabindex:"-1"},[t("1. "),e("a",{class:"header-anchor",href:"#_1","aria-hidden":"true"},"#")],-1),h=e("div",{class:"danger custom-block"},[e("p",{class:"custom-block-title"},"Error"),e("p",null,"Could not find a version that satisfies the requirement cmarkgfm==0.5.0 (from versions: 0.1.0al, 0.1.0a2, 0.1.0, ...) ERROR: No matching distribution found for cmarkgfm==0.5.0")],-1),u=e("h3",{id:"solution",tabindex:"-1"},[t("Solution "),e("a",{class:"header-anchor",href:"#solution","aria-hidden":"true"},"#")],-1),_=e("p",null,[t("Go in the "),e("a",{href:"http://requirements.in",target:"_blank",rel:"noopener noreferrer"},"requirements.in"),t(" file and change around the 'cmarkgfm' version number. My occurring error got fixed with changing it to 0.6.0 in the config file fixed it")],-1),m=e("h2",{id:"_2",tabindex:"-1"},[t("2. "),e("a",{class:"header-anchor",href:"#_2","aria-hidden":"true"},"#")],-1),f=e("div",{class:"danger custom-block"},[e("p",{class:"custom-block-title"},"Error"),e("p",null,`TypeError: "time" is an invalid keyword argument for QuizChallengeModel ctfd 1 1 172-18-0.1 --[25/Nov/2021:10:57:41+0000] "POST /api/v1/challenges HTTP/1.1" 500 37 "http: //loc ctfd 1 | sqlalchemy.exc. InvalidRequestError: Table "quiz _challenge model' is already defined for this Meti stance. Specify "extend existing=True' to redefine options and columns on an existing Table object. ctfd-proofofconcept ctfd_l exited with code 1`)],-1),p=e("h3",{id:"solution-1",tabindex:"-1"},[t("Solution "),e("a",{class:"header-anchor",href:"#solution-1","aria-hidden":"true"},"#")],-1),g=e("p",null,'This Error occurred while programming a new plugin that is using a newly added field type (like "time"). This can be fixed du to fulfilling a database migration, so the database knows how to deal with the new column name such as "time".',-1),v=e("h2",{id:"_3",tabindex:"-1"},[t("3. "),e("a",{class:"header-anchor",href:"#_3","aria-hidden":"true"},"#")],-1),b=e("div",{class:"danger custom-block"},[e("p",{class:"custom-block-title"},"Error"),e("p",null,[t("ctfd_1 | [SQL: INSERT INTO quiz_challenge_model (id, timer, variant_a, variant_b, variant_c, variant_d, correct_variant) VALUES (%(id)s, %(timer)s, %(variant_a)s, %(variant_b)s, %(variant_c)s, %(variant_d)s, %(correct_variant)s)] ctfd_1 | [parameters: {'id': 4, 'timer': '2', 'variant_a': '2', 'variant_b': '2', 'variant_c': '2', 'variant_d': '2', 'correct_variant': 'B'}] ctfd_1 | (Background on this error at: "),e("a",{href:"http://sqlalche.me/e/2j85",target:"_blank",rel:"noopener noreferrer"},"http://sqlalche.me/e/2j85"),t(') ctfd_1 | 172.18.0.1 - - [25/Nov/2021:11:07:16 +0000] "POST /api/v1/challenges HTTP/1.1" 500 37 "'),e("a",{href:"http://localhost:8000/admin/challenges/new",target:"_blank",rel:"noopener noreferrer"},"http://localhost:8000/admin/challenges/new"),t('" "Mozilla/5.0 (Macintosh; Intel Mac OS X 10_15_7)"')])],-1),k=e("h3",{id:"solution-2",tabindex:"-1"},[t("Solution "),e("a",{class:"header-anchor",href:"#solution-2","aria-hidden":"true"},"#")],-1),x=e("p",null,"Exception is raised when the database encounters an internal error, e.g. the cursor is not valid anymore, the transaction is out of sync, etc. This error is a DBAPI Error and originates from the database driver (DBAPI), not SQLAlchemy itself. The InternalError is sometimes raised by drivers in the context of the database connection being dropped, or not being able to connect to the database.",-1),T=e("h2",{id:"_4",tabindex:"-1"},[t("4. "),e("a",{class:"header-anchor",href:"#_4","aria-hidden":"true"},"#")],-1),E=e("div",{class:"danger custom-block"},[e("p",{class:"custom-block-title"},"Error"),e("p",null,'ERROR [CTFd] Exception on /api/v1/challenges/13 [GET] ctfd_1 | Traceback (most recent call last): ctfd_1 | File "/usr/local/lib/python3.7/site-packages/flask/app.py", line 1950, in full_dispatch_request')],-1),w=e("h3",{id:"solution-3",tabindex:"-1"},[t("Solution "),e("a",{class:"header-anchor",href:"#solution-3","aria-hidden":"true"},"#")],-1),S=e("p",null,"The Error occurred when the API had to fetch a data type that it didn't know. The solution was to update the variable name via a migration.",-1),y=[s,l,c,d,h,u,_,m,f,p,g,v,b,k,x,T,E,w,S];function q(I,P,R,B,N,A){return r(),o("div",null,y)}var O=a(i,[["render",q]]);export{M as __pageData,O as default};
